Workbook

Sheet Invoice
A1: SHANGHAI PUCCI TEXTILE CO., LTD
A2: Unit 103, Block 1, No. 218 Huting North Road, Songjiang District, Shanghai,China | I2: PO # | J2: 04758
A3: ATTN:SHERRY TEL:18616981368 | I3: Invoice # | J3: PT04758D
I4: Date | J4: 46188
A6: Manufacturer Name:SHANGHAI PUCCI TEXTILE CO., LTD | I6: Shipping Mode | J6: Air
A7: Manufacturer address;Unit 103, Block 1, No. 218 Huting North Road, | I7: Shipment #
A8: Songjiang District, Shanghai,China | I8: ETA Date
A9: ATTN:SHERRY TEL:18616981368 | I9: Port of Loading | J9: Shanghai,China
I10: Port of Discharge | J10: Vancouver,Canada
I11: Remarks
A12: Commercial invoice | I12: Country of Origin | J12: China
A14: Consignee | D14: Notify Party
A15: NRI CA Warehouse | D15: Tentree International
A16: 8205 Dallas Dr., Kamloops | D16: 230-1275 Venables St.
A17: British Columbia Canada | D17: Vancouver, BC V6A 2E4
D18: 604-829-2706
A21: PO# | B21: SKU | C21: UPC | D21: Knit/Woven | E21: Style Description | F21: Color Description | G21: Category | H21: Gender | I21: Composition | J21: HTS Code | K21: Quantity | L21: Unit Price USD | M21: Total USD
A22: PO04758 | B22: TCM6140-6412-L | C22: 661814900094 | D22: Knit | E22: M Howson Hoodie | F22: Dark Forest Green/Pine Green | G22: Hoodie | H22: Mens | I22: 55% Organic Cotton, 26% Recycled Polyester, 19% TENCEL™ Lyocell | J22: 6109.10.00.10 | K22: 10 | L22: 16.94 | M22: =K22*L22 -> 169.4
A23: PO04758 | B23: TCM6140-6412-M | C23: 661814899183 | D23: Knit | E23: M Howson Hoodie | F23: Dark Forest Green/Pine Green | G23: Hoodie | H23: Mens | I23: 55% Organic Cotton, 26% Recycled Polyester, 19% TENCEL™ Lyocell | J23: 6109.10.00.10 | K23: 10 | L23: 16.94 | M23: =K23*L23 -> 169.4
A24: PO04758 | B24: TCM6140-6412-S | C24: 661814899169 | D24: Knit | E24: M Howson Hoodie | F24: Dark Forest Green/Pine Green | G24: Hoodie | H24: Mens | I24: 55% Organic Cotton, 26% Recycled Polyester, 19% TENCEL™ Lyocell | J24: 6109.10.00.10 | K24: 5 | L24: 16.94 | M24: =K24*L24 -> 84.7
A25: PO04758 | B25: TCM6140-6412-XL | C25: 661814899145 | D25: Knit | E25: M Howson Hoodie | F25: Dark Forest Green/Pine Green | G25: Hoodie | H25: Mens | I25: 55% Organic Cotton, 26% Recycled Polyester, 19% TENCEL™ Lyocell | J25: 6109.10.00.10 | K25: 10 | L25: 16.94 | M25: =K25*L25 -> 169.4
A26: PO04758 | B26: TCM6140-6412-XXL | C26: 661814899121 | D26: Knit | E26: M Howson Hoodie | F26: Dark Forest Green/Pine Green | G26: Hoodie | H26: Mens | I26: 55% Organic Cotton, 26% Recycled Polyester, 19% TENCEL™ Lyocell | J26: 6109.10.00.10 | K26: 5 | L26: 16.94 | M26: =K26*L26 -> 84.7
A27: PO04758 | B27: TCM6140-5758-L | C27: 661814899268 | D27: Knit | E27: M Howson Hoodie | F27: Harbour Grey Heather/Midnight Blue | G27: Hoodie | H27: Mens | I27: 55% Organic Cotton, 26% Recycled Polyester, 19% TENCEL™ Lyocell | J27: 6109.10.00.10 | K27: 2 | L27: 16.45 | M27: =K27*L27 -> 32.9
A28: PO04758 | B28: TCM6140-5758-M | C28: 661814899244 | D28: Knit | E28: M Howson Hoodie | F28: Harbour Grey Heather/Midnight Blue | G28: Hoodie | H28: Mens | I28: 55% Organic Cotton, 26% Recycled Polyester, 19% TENCEL™ Lyocell | J28: 6109.10.00.10 | K28: 1 | L28: 16.45 | M28: =K28*L28 -> 16.45
A29: PO04758 | B29: TCM6140-5758-S | C29: 661814899220 | D29: Knit | E29: M Howson Hoodie | F29: Harbour Grey Heather/Midnight Blue | G29: Hoodie | H29: Mens | I29: 55% Organic Cotton, 26% Recycled Polyester, 19% TENCEL™ Lyocell | J29: 6109.10.00.10 | K29: 1 | L29: 16.45 | M29: =K29*L29 -> 16.45
A30: PO04758 | B30: TCM6140-5758-XL | C30: 661814899206 | D30: Knit | E30: M Howson Hoodie | F30: Harbour Grey Heather/Midnight Blue | G30: Hoodie | H30: Mens | I30: 55% Organic Cotton, 26% Recycled Polyester, 19% TENCEL™ Lyocell | J30: 6109.10.00.10 | K30: 1 | L30: 16.45 | M30: =K30*L30 -> 16.45
A31: PO04758 | B31: TCM6140-6489-L | C31: 661814899008 | D31: Knit | E31: M Howson Hoodie | F31: Meteorite Black/Cider | G31: Hoodie | H31: Mens | I31: 55% Organic Cotton, 26% Recycled Polyester, 19% TENCEL™ Lyocell | J31: 6109.10.00.10 | K31: 2 | L31: 16.45 | M31: =K31*L31 -> 32.9
A32: PO04758 | B32: TCM6140-6489-M | C32: 661814898995 | D32: Knit | E32: M Howson Hoodie | F32: Meteorite Black/Cider | G32: Hoodie | H32: Mens | I32: 55% Organic Cotton, 26% Recycled Polyester, 19% TENCEL™ Lyocell | J32: 6109.10.00.10 | K32: 2 | L32: 16.45 | M32: =K32*L32 -> 32.9
A33: PO04758 | B33: TCM6140-6489-S | C33: 661814898988 | D33: Knit | E33: M Howson Hoodie | F33: Meteorite Black/Cider | G33: Hoodie | H33: Mens | I33: 55% Organic Cotton, 26% Recycled Polyester, 19% TENCEL™ Lyocell | J33: 6109.10.00.10 | K33: 2 | L33: 16.45 | M33: =K33*L33 -> 32.9
... A188: PO04758 | B188: TCW6652-6293-XS | C188: 661814874852 | D188: Knit | E188: W Vancouver Dress | F188: Red Chestnut | G188: Dress | H188: Womens | I188: 55% Organic Cotton, 26% Recycled Polyester, 19% TENCEL™ Lyocell | J188: 6109.10.00.10 | K188: 2 | L188: 15 | M188: =K188*L188 -> 30
K196: =SUM(K22:K195) -> 1437 | M196: =SUM(M22:M195) -> 28394.63
A197: Say Tn Words Total US Dollars: | C197: Twenty Eight Thousand Three Thousand and Ninety Four and Cents Sixty Three only.
A200: Additional Remarks
H205: Seller Full Company Name and Adress :
H206: SHANGHAI PUCCI TEXTILE CO., LTD
H207: UNIT 103, BLOCK 1, NO. 218 HUTING NORTH ROAD, SONGJIANG DISTRICT,SHANGHAI,CHINA
H213: (Authorized Signature/ Company Mark)

Sheet Packing List
A1: SHANGHAI PUCCI TEXTILE CO., LTD
A2: ROOM 401, BUILDING 19, NO. 900 HUTING NORTH ROAD, SONGJIANG DISTRICT, SHANGHAI, CHINA
A3: ATTN:SHERRY TEL:86-21-37705691 | E3: ATTN:SHERRY TEL:86-21-37705691
A4: Packing List
A5: Consignee | E5: Notify Party | G5: PO # | H5: =Invoice!J2 -> 04758
A6: =Invoice!A15 -> NRI CA Warehouse | E6: =Invoice!D15 -> Tentree International | G6: Invoice NO. | H6: =Invoice!J3 -> PT04758D
A7: =Invoice!A16 -> 8205 Dallas Dr., Kamloops | E7: =Invoice!D16 -> 230-1275 Venables St. | G7: S/C NO.
A8: =Invoice!A17 -> British Columbia Canada | E8: =Invoice!D17 -> Vancouver, BC V6A 2E4 | G8: Packinglist No.
E9: =Invoice!D18 -> 604-829-2706 | G9: DATE: | H9: =Invoice!J4 -> 46188
G10: PAGE: | H10: 1
A12: CTN # | B12: PO # | C12: SKU# | D12: UPC | E12: Style Description | F12: Color Description | G12: PCS/CTN | H12: N/W(KGS) | I12: G/W(KGS) | J12: MEASURE
A13: 1# | B13: 04758 | C13: TCM6140-5758-S | D13: 661814899220 | E13: M Howson Hoodie | F13: Harbour Grey Heather/Midnight Blue | G13: 1 | H13: 11 | I13: 12 | J13: 52X34X40CM
B14: 04758 | C14: TCM6140-5758-M | D14: 661814899244 | E14: M Howson Hoodie | F14: Harbour Grey Heather/Midnight Blue | G14: 1
B15: 04758 | C15: TCM6140-5758-L | D15: 661814899268 | E15: M Howson Hoodie | F15: Harbour Grey Heather/Midnight Blue | G15: 2
B16: 04758 | C16: TCM6140-5758-XL | D16: 661814899206 | E16: M Howson Hoodie | F16: Harbour Grey Heather/Midnight Blue | G16: 1
B17: 04758 | C17: TCM6140-6488-L | D17: 661814899107 | E17: M Howson Hoodie | F17: Red Chestnut/Ashwood | G17: 1
B18: 04758 | C18: TCM6140-6488-M | D18: 661814899084 | E18: M Howson Hoodie | F18: Red Chestnut/Ashwood | G18: 1
B19: 04758 | C19: TCM6140-6488-XL | D19: 661814899046 | E19: M Howson Hoodie | F19: Red Chestnut/Ashwood | G19: 1
B20: 04758 | C20: TCM6140-6489-S | D20: 661814898988 | E20: M Howson Hoodie | F20: Meteorite Black/Cider | G20: 2
B21: 04758 | C21: TCM6140-6489-M | D21: 661814898995 | E21: M Howson Hoodie | F21: Meteorite Black/Cider | G21: 2
B22: 04758 | C22: TCM6140-6489-L | D22: 661814899008 | E22: M Howson Hoodie | F22: Meteorite Black/Cider | G22: 2
B23: 04758 | C23: TCM6140-6489-XL | D23: 661814898971 | E23: M Howson Hoodie | F23: Meteorite Black/Cider | G23: 2
B24: 04758 | C24: TCM6140-6489-XXL | D24: 661814898964 | E24: M Howson Hoodie | F24: Meteorite Black/Cider | G24: 1
B25: 04758 | C25: TCM6140-6412-XXL | D25: 661814899121 | E25: M Howson Hoodie | F25: Dark Forest Green/Pine Green | G25: 1
A26: 2# | B26: 04758 | C26: TCM6140-6412-M | D26: 661814899183 | E26: M Howson Hoodie | F26: Dark Forest Green/Pine Green | G26: 10 | H26: 11 | I26: 12 | J26: 52X34X40CM
B27: 04758 | C27: TCM6140-6412-L | D27: 661814900094 | E27: M Howson Hoodie | F27: Dark Forest Green/Pine Green | G27: 10
A28: 3# | B28: 04758 | C28: TCM6140-6412-S | D28: 661814899169 | E28: M Howson Hoodie | F28: Dark Forest Green/Pine Green | G28: 5 | H28: 11 | I28: 12 | J28: 52X34X40CM
B29: 04758 | C29: TCM6140-6412-XL | D29: 661814899145 | E29: M Howson Hoodie | F29: Dark Forest Green/Pine Green | G29: 10
B30: 04758 | C30: TCM6140-6412-XXL | D30: 661814899121 | E30: M Howson Hoodie | F30: Dark Forest Green/Pine Green | G30: 4
A31: 4# | B31: 04758 | C31: TCM6673-6438-M | D31: 661814882079 | E31: M Heritage Landscape Full Zip Hoodie | F31: Ashwood/Meteorite Black | G31: 2 | H31: 11 | I31: 12 | J31: 52X34X40CM
B32: 04758 | C32: TCM6673-6438-L | D32: 661814881539 | E32: M Heritage Landscape Full Zip Hoodie | F32: Ashwood/Meteorite Black | G32: 3
B33: 04758 | C33: TCM6673-6438-XL | D33: 661814887791 | E33: M Heritage Landscape Full Zip Hoodie | F33: Ashwood/Meteorite Black | G33: 2
B34: 04758 | C34: TCM6673-6461-XXL | D34: 661814887678 | E34: M Heritage Landscape Full Zip Hoodie | F34: Deep Olive/White Oak | G34: 11
A35: 5# | B35: 04758 | C35: TCM6673-6461-M | D35: 661814887739 | E35: M Heritage Landscape Full Zip Hoodie | F35: Deep Olive/White Oak | G35: 18 | H35: 11 | I35: 12 | J35: 52X34X40CM
A36: 6# | B36: 04758 | C36: TCM6673-6461-M | D36: 661814887739 | E36: M Heritage Landscape Full Zip Hoodie | F36: Deep Olive/White Oak | G36: 18 | H36: 11 | I36: 12 | J36: 52X34X40CM
A37: 7# | B37: 04758 | C37: TCM6673-6461-L | D37: 661814887753 | E37: M Heritage Landscape Full Zip Hoodie | F37: Deep Olive/White Oak | G37: 18 | H37: 11 | I37: 12 | J37: 52X34X40CM
A38: 8# | B38: 04758 | C38: TCM6673-6461-L | D38: 661814887753 | E38: M Heritage Landscape Full Zip Hoodie | F38: Deep Olive/White Oak | G38: 18 | H38: 11 | I38: 12 | J38: 52X34X40CM
A39: 9# | B39: 04758 | C39: TCM6673-6461-L | D39: 661814887753 | E39: M Heritage Landscape Full Zip Hoodie | F39: Deep Olive/White Oak | G39: 18 | H39: 11 | I39: 12 | J39: 52X34X40CM
A40: 10# | B40: 04758 | C40: TCM6673-6461-XL | D40: 661814887692 | E40: M Heritage Landscape Full Zip Hoodie | F40: Deep Olive/White Oak | G40: 18 | H40: 11 | I40: 12 | J40: 52X34X40CM
A41: 11# | B41: 04758 | C41: TCM6673-6461-XL | D41: 661814887692 | E41: M Heritage Landscape Full Zip Hoodie | F41: Deep Olive/White Oak | G41: 18 | H41: 11 | I41: 12 | J41: 52X34X40CM
...
