Workbook
Name \b: #REF!
Name \d: #REF!
Name \f: #REF!
Name \i: #REF!
Name \k: #REF!
Name \l: #REF!
Name \p: #REF!
Name \s: #REF!
Name \w: #REF!
Name _?1: IF(OR(#REF!=0,#REF!=""),"","~")
Name _?2: IF(OR(#REF!="",#REF!=0,#REF!="",#REF!=0),0,IF(#REF!-#REF!=1,0,IF(#REF!=#REF!,0,#REF!-1)))
Name _?3: IF(OR(#REF!="",#REF!=""),IF(#REF!="",0,IF(#REF!=#REF!,0,1)),IF(#REF!=#REF!,IF(#REF!<>#REF!,1,0),IF(#REF!=#REF!,0,IF(OR(#REF!=0,#REF!=""),1,#REF!-#REF!+1))))
Name _?4: IF(#REF!=0,SUM(#REF!),SUM(#REF!)*#REF!)
Name _______________xlfn_IFERROR: #N/A
Name ______________xlfn_IFERROR: "#N/A"
Name _____________xlfn_IFERROR: "#N/A"
Name ____________xlfn_IFERROR: "#N/A"
Name ___________xlfn_IFERROR: "#N/A"
Name __________xlfn_IFERROR: "#N/A"
Name __________z: NA()
Name _________xlfn_IFERROR: "#N/A"
Name _________z: NA()
Name ________0_1: "#REF!"
Name ________Reg10: [1]Sheet3!$H$34:$H$38
Name ________Reg2: [1]Sheet3!$H$5:$H$12
Name ________Reg3: [1]Sheet3!$H$13
Name ________Reg4: [1]Sheet3!$H$14:$H$18
Name ________Reg5: [1]Sheet3!$H$19:$H$20
Name ________Reg6: [1]Sheet3!$H$21:$H$26
Name ________Reg7: [1]Sheet3!$H$27
Name ________Reg8: [1]Sheet3!$H$28:$H$32
Name ________Reg9: [1]Sheet3!$H$33
Name ________xlfn_IFERROR: "#N/A"
Name ________z: NA()
Name _______0_1: "#REF!"
Name _______0_2: "#REF!"
Name _______b: "#REF!"
Name _______d: "#REF!"
Name _______f: "#REF!"
Name _______i: "#REF!"
Name _______k: "#REF!"
Name _______l: "#REF!"
Name _______p: "#REF!"
Name _______Reg1: #REF!
Name _______Reg10: #REF!
Name _______Reg2: #REF!
Name _______Reg3: [1]Sheet3!$H$13
Name _______Reg4: #REF!
Name _______Reg5: #REF!
Name _______Reg6: #REF!
Name _______Reg7: [1]Sheet3!$H$27
Name _______Reg8: #REF!
Name _______Reg9: [1]Sheet3!$H$33
Name _______s: "#REF!"
Name _______w: "#REF!"
Name _______xlfn_IFERROR: "#N/A"
Name _______z: NA()
Name ______0_1: "#REF!"
Name ______0_2: "#REF!"
Name ______b: "#REF!"

Sheet INV-PO04774
A2: CONTINENT 8 PTE LTD | H2: PO # | I2: PO04774
A3: 300 TAMPINES AVENUE 5, #. 09-02, | H3: Invoice # | I3: 022C8P2605AW26
A4: INCOME AT TAMPINES JUNCTION SINGAPORE 529653 | H4: Date | I4: 46149
A5: AT TAMPINES JUNCTION SINGAPORE 529653 | H5: Shipping Mode | I5: SEA (INCRES 072N)
H6: Shipment # | I6: LGINBSHIP000798
A7: Manufacturer : | H7: ETD Date | I7: 46153
A8: PT. MASTERINDO JAYA ABADI | H8: ETA Date | I8: 46203
A9: JL. SOEKARNO HATTA NO. 24 | H9: Port of Loading | I9: JAKARTA, INDONESIA
A10: BANDUNG 40212, INDONESIA 50512 | H10: Port of Discharge | I10: LOS ANGLES, USA
A11: TAX ID#. 001.280.264.1-441.000 | H11: Remarks
A12: Commercial invoice | H12: Country of Origin | I12: INDONESIA
A14: Consignee | D14: Notify Party
A15: Tentree c/o NRI Distribution Inc. | D15: Tentree International Canada
A16: 9988 Redwood Avenue | D16: 230-1275 Venables St.
A17: LH Building | D17: Vancouver, BC V6A 2E4
A18: Fontana, California | D18: Canada
A19: 1.323.345.6456 | D19: +7789897887
A20: 92335, United States | D20: logstics@tentree.com
A21: Contact: Yarumi Padilla
A22: 1.323.345.6456
A23: yarumi.padilla@nri-distribution.com
A24: Carrier Appointment Email
A25: appt-LH@nri distribution.com
A27: PO# | B27: STYLE-COLOR | C27: Knit/Woven | D27: Style Description | E27: Color Description | F27: Category | G27: Gender | H27: Composition | I27: HTS Code | J27: Quantity | K27: Unit Price USD | L27: Total USD
A28: =I2 -> PO04774 | B28: TCW6649-6303 | C28: Knit | D28: W Flint Pant | E28: Ashwood | F28: Pants | G28: Womens | H28: 53% Organic Cotton, 45% Recycled Polyester, 2% Spandex | I28: 6104.62.62.20 | J28: 40 | K28: 23.35 | L28: =J28*K28 -> 934 | M28: 39.69 | N28: 52.92
A29: =A28 -> PO04774 | B29: TCW6649-0164 | C29: Knit | D29: =D28 -> W Flint Pant | E29: Meteorite Black | F29: Pants | G29: Womens | H29: 53% Organic Cotton, 45% Recycled Polyester, 2% Spandex | I29: 6104.62.62.20 | J29: 49 | K29: 23.35 | L29: =J29*K29 -> 1144.15
A30: =A28 -> PO04774 | B30: TCM6684-6303 | C30: Knit | D30: M Clark Pant | E30: Ashwood | F30: Pants | G30: Mens | H30: 53% Organic Cotton, 45% Recycled Polyester, 2% Spandex | I30: 6103.42.62.20 | J30: 50 | K30: 25.4 | L30: =J30*K30 -> 1270 | M30: 45 | N30: 60
A31: =A28 -> PO04774 | B31: TCM6684-0164 | C31: Knit | D31: =D30 -> M Clark Pant | E31: Meteorite Black | F31: Pants | G31: Mens | H31: =H30 -> 53% Organic Cotton, 45% Recycled Polyester, 2% Spandex | I31: 6103.42.62.20 | J31: 42 | K31: 25.4 | L31: =J31*K31 -> 1066.8
A32: =A30 -> PO04774 | B32: TCW6648-6303 | C32: Woven | D32: W Breton Pant | E32: Ashwood | F32: Pants | G32: Womens | H32: 90% Recycled Polyester, 10% Spandex | I32: 6204.63.62.10 | J32: 79 | K32: 21.85 | L32: =J32*K32 -> 1726.15 | M32: 48.12 | N32: 64.16
A33: =A28 -> PO04774 | B33: TCW6648-0164 | C33: Woven | D33: W Breton Pant | E33: Meteorite Black | F33: Pants | G33: Womens | H33: 90% Recycled Polyester, 10% Spandex | I33: 6204.63.62.10 | J33: 75 | K33: 21.85 | L33: =J33*K33 -> 1638.75
A34: =A28 -> PO04774 | B34: TCM6685-0164 | C34: Woven | D34: M Cameron Pant | E34: Meteorite Black | F34: Pants | G34: Mens | H34: 90% Recycled Polyester, 10% Spandex | I34: 6203.43.62.10 | J34: =+'PL-PO04774'!N118 -> 47 | K34: 27.48 | L34: =J34*K34 -> 1291.56 | M34: 73.86
A35: =A32 -> PO04774 | B35: TCM6685-6289 | C35: Woven | D35: M Cameron Pant | E35: Cedar Bark | F35: Pants | G35: Mens | H35: 90% Recycled Polyester, 10% Spandex | I35: 6203.43.62.10 | J35: =+'PL-PO04774'!N119 -> 35 | K35: 27.48 | L35: =J35*K35 -> 961.8 | M35: 73.86 | N35: 98.48
A36: =A35 -> PO04774 | B36: TCW7113-6303 | C36: Woven | D36: W Cowen Pant | E36: Ashwood | F36: Pants | G36: Womens | H36: 90% Recycled Polyester, 10% Spandex | I36: 6204.63.62.10 | J36: 41 | K36: 22.5 | L36: =J36*K36 -> 922.5 | M36: 50.01 | N36: 66.68
A37: =A28 -> PO04774 | B37: TCW7113-0164 | C37: Woven | D37: W Cowen Pant | E37: Meteorite Black | F37: Pants | G37: Womens | H37: 90% Recycled Polyester, 10% Spandex | I37: 6204.63.62.10 | J37: 27 | K37: 22.5 | L37: =J37*K37 -> 607.5
A38: =A36 -> PO04774 | B38: TCM6797-0164 | C38: Woven | D38: M Simcoe Pant | E38: Meteorite Black | F38: Pants | G38: Mens | H38: 90% Recycled Polyester, 10% Spandex | I38: 6203.43.62.10 | J38: 46 | K38: 22.11 | L38: =J38*K38 -> 1017.06 | M38: 38.14 | N38: 57.21
A39: =A30 -> PO04774 | B39: TCW5674-6391 | C39: Woven | D39: W Yaletown Skirt | E39: Meteorite Black/Meadowland Ditsy | F39: Pants | G39: Womens | H39: 100% ECOVERO -Sustainable Viscose by Lenzing | I39: 6204.63.62.10 | J39: 149 | K39: 14.73 | L39: =J39*K39 -> 2194.77 | M39: 23.1 | N39: 34.65
J41: =SUM(J28:J40) -> 680 | L41: =SUM(L28:L40) -> 14775.04
A42: Say Tn Words Total US Dollars: | C42: Fourteen thousand seven hundred seventy five ad cents four only | M42: =J41+'INV-PO04786'!J35 -> 819 | P42: =52.92*6 -> 317.52
P43: 160
A44: Additional Remarks
...

Sheet PL-PO04774
A1: =+'INV-PO04774'!A2 -> CONTINENT 8 PTE LTD
A2: =+'INV-PO04774'!A3 -> 300 TAMPINES AVENUE 5, #. 09-02,
A3: =+'INV-PO04774'!A4 -> INCOME AT TAMPINES JUNCTION SINGAPORE 529653
A4: =+'INV-PO04774'!A5 -> AT TAMPINES JUNCTION SINGAPORE 529653
A5: PACKING LIST
J6: PO # | K6: =+'INV-PO04774'!I2 -> PO04774
A7: Consignee | F7: Notify Party | J7: Invoice NO. | K7: =+'INV-PO04774'!I3 -> 022C8P2605AW26
A8: =+'INV-PO04774'!A15 -> Tentree c/o NRI Distribution Inc. | F8: =+'INV-PO04774'!D15 -> Tentree International Canada | J8: S/C NO. | K8: -
A9: =+'INV-PO04774'!A16 -> 9988 Redwood Avenue | F9: =+'INV-PO04774'!D16 -> 230-1275 Venables St. | J9: Packinglist No. | K9: =K7 -> 022C8P2605AW26
A10: =+'INV-PO04774'!A17 -> LH Building | F10: =+'INV-PO04774'!D17 -> Vancouver, BC V6A 2E4 | J10: DATE: | K10: =+'INV-PO04774'!I4 -> 46149
A11: =+'INV-PO04774'!A18 -> Fontana, California | F11: =+'INV-PO04774'!D18 -> Canada | J11: PAGE: | K11: 1-2, 2-2,3-3
A12: =+'INV-PO04774'!A19 -> 1.323.345.6456 | F12: =+'INV-PO04774'!D19 -> +7789897887
A13: =+'INV-PO04774'!A20 -> 92335, United States | F13: =+'INV-PO04774'!D20 -> logstics@tentree.com
A14: =+'INV-PO04774'!A21 -> Contact: Yarumi Padilla
A15: =+'INV-PO04774'!A22 -> 1.323.345.6456
A16: =+'INV-PO04774'!A23 -> yarumi.padilla@nri-distribution.com
A17: =+'INV-PO04774'!A24 -> Carrier Appointment Email
A19: CTN # | D19: PO # | E19: SKU | F19: UPC | G19: Style Description | H19: Color Description | I19: TOTAL CTN | J19: TOTAL PCS/CTN | K19: TOTAL PCS | L19: N/W (Kgs) | M19: G/W (Kgs) | N19: MEASURE (M3) | O19: MEASURE (CM)
A21: 1 | B21: - | C21: =+A21+I21-1 -> 1 | D21: =K6 -> PO04774 | E21: TCW6649-6303-2 | F21: 661814875897 | G21: =+'INV-PO04774'!D28 -> W Flint Pant | H21: =+'INV-PO04774'!E28 -> Ashwood | I21: 1 | J21: 1 | K21: =J21+J22+J23+J24 -> 24 | L21: =540*J21/1000+560*J22/1000+580*J23/1000+600*J24/1000 -> 14 | M21: =1.65+L21 -> 15.65 | N21: 80 X 44 X 25 | O21: 2 | P21: 285 | Q21: 661814875897 | R21: 2
E22: TCW6649-6303-4 | F22: 661814875873 | J22: 6 | Q22: 661814875873 | R22: 4
E23: TCW6649-6303-6 | F23: 661814875859 | J23: 5 | Q23: 661814875859 | R23: 6
E24: TCW6649-6303-8 | F24: 661814875835 | J24: 12 | Q24: 661814875835 | R24: 8
A25: =A21+I21 -> 2 | B25: - | C25: =+A25+I25-1 -> 2 | E25: TCW6649-6303-10 | F25: 661814875972 | I25: 1 | J25: 9 | K25: =J25+J26+J27+J28 -> 16 | L25: =620*J25/1000+640*J26/1000+660*J27/1000+680*J28/1000 -> 10.14 | M25: =1.65+L25 -> 11.79 | N25: 80 X 44 X 15 | Q25: 661814875972 | R25: 10
E26: TCW6649-6303-12 | F26: 661814875958 | J26: 4 | Q26: 661814875958 | R26: 12
E27: TCW6649-6303-14 | F27: 661814875934 | J27: 2 | Q27: 661814875934 | R27: 14
E28: TCW6649-6303-16 | F28: 661814875910 | J28: 1 | Q28: 661814875910 | R28: 16
A29: =A25+I25 -> 3 | B29: - | C29: =+A29+I29-1 -> 3 | E29: TCW6649-0164-2 | F29: 661814876030 | H29: =+'INV-PO04774'!E29 -> Meteorite Black | I29: 1 | J29: 2 | K29: =J29+J30+J31+J32 -> 30 | L29: =540*J29/1000+560*J30/1000+580*J31/1000+600*J32/1000 -> 17.46 | M29: =1.65+L29 -> 19.11 | N29: 80 X 44 X 25 | Q29: 661814876030 | R29: 2
E30: TCW6649-0164-4 | F30: 661814876016 | J30: 8 | Q30: 661814876016 | R30: 4
E31: TCW6649-0164-6 | F31: 661814875996 | J31: 5 | Q31: 661814875996 | R31: 6
E32: TCW6649-0164-8 | F32: 661814876054 | J32: 15 | Q32: 661814876054 | R32: 8
A33: =A29+I29 -> 4 | B33: - | C33: =+A33+I33-1 -> 4 | E33: TCW6649-0164-10 | F33: 661814876139 | I33: 1 | J33: 10 | K33: =J33+J34+J35+J36 -> 19 | L33: =620*J33/1000+640*J34/1000+660*J35/1000+680*J36/1000 -> 12.1 | M33: =1.65+L33 -> 13.75 | N33: 80 X 44 X 15 | Q33: 661814876139 | R33: 10
E34: TCW6649-0164-12 | F34: 661814876115 | J34: 4 | Q34: 661814876115 | R34: 12
E35: TCW6649-0164-14 | F35: 661814876092 | J35: 3 | Q35: 661814876092 | R35: 14
E36: TCW6649-0164-16 | F36: =Q36 -> 661814876078 | J36: 2 | O36: 4 | P36: 288 | Q36: 661814876078 | R36: 16
A37: 1 | B37: - | C37: =+A37+I37-1 -> 1 | D37: =K6 -> PO04774 | E37: TCM6684-6303-30 | F37: 661814885612 | G37: =+'INV-PO04774'!D30 -> M Clark Pant | H37: =+'INV-PO04774'!E30 -> Ashwood | I37: 1 | J37: 4 | K37: =J37+J38+J39+J40 -> 29 | L37: =540*J37/1000+560*J38/1000+580*J39/1000+600*J40/1000 -> 16.74 | M37: =1.65+L37 -> 18.39 | N37: 80 X 44 X 25 | O37: 2 | P37: 285 | Q37: 661814885612 | R37: 30
E38: TCM6684-6303-31 | F38: 661814885599 | J38: 8 | Q38: 661814885599 | R38: 31
E39: TCM6684-6303-32 | F39: 661814885575 | J39: 5 | Q39: 661814885575 | R39: 32
E40: TCM6684-6303-33 | F40: 661814885551 | J40: 12 | Q40: 661814885551 | R40: 33
A41: =A37+I37 -> 2 | B41: - | C41: =+A41+I41-1 -> 2 | E41: TCM6684-6303-34 | F41: 661814885537 | I41: 1 | J41: 10 | K41: =J41+J42+J43+J44 -> 21 | L41: =620*J41/1000+640*J42/1000+660*J43/1000+680*J44/1000 -> 13.54 | M41: =1.65+L41 -> 15.19 | N41: 80 X 44 X 25 | Q41: 661814885537 | R41: 34
E42: TCM6684-6303-36 | F42: 661814885513 | J42: 2 | Q42: 661814885513 | R42: 36
...

Sheet INV-PO04786
A2: CONTINENT 8 PTE LTD | H2: PO # | I2: PO04786
A3: 300 TAMPINES AVENUE 5, #. 09-02, | H3: Invoice # | I3: 022C8P2605AW26.A
A4: INCOME AT TAMPINES JUNCTION SINGAPORE 529653 | H4: Date | I4: 46149
A5: AT TAMPINES JUNCTION SINGAPORE 529653 | H5: Shipping Mode | I5: SEA (INCRES 072N)
H6: Shipment # | I6: LGINBSHIP000798
A7: Manufacturer : | H7: ETD Date | I7: 46153
A8: PT. MASTERINDO JAYA ABADI | H8: ETA Date | I8: 46203
A9: JL. SOEKARNO HATTA NO. 24 | H9: Port of Loading | I9: JAKARTA, INDONESIA
A10: BANDUNG 40212, INDONESIA 50512 | H10: Port of Discharge | I10: LOS ANGLES, USA
A11: TAX ID#. 001.280.264.1-441.000 | H11: Remarks
A12: Commercial invoice | H12: Country of Origin | I12: INDONESIA
A14: Consignee | D14: Notify Party
A15: Tentree c/o NRI Distribution Inc. - RECEIVING | D15: Tentree International Canada
A16: 9988 Redwood Avenue | D16: 230-1275 Venables St.
A17: LH Building | D17: Vancouver, BC V6A 2E4
A18: Fontana, California | D18: Canada
A19: 1.323.345.6456 | D19: +7789897887
A20: 92335, United States | D20: logstics@tentree.com
A21: Contact: Yarumi Padilla
A22: 1.323.345.6456
A23: yarumi.padilla@nri-distribution.com
A24: Carrier Appointment Email
A25: appt-LH@nri distribution.com
A27: PO# | B27: STYLE-COLOR | C27: Knit/Woven | D27: Style Description | E27: Color Description | F27: Category | G27: Gender | H27: Composition | I27: HTS Code | J27: Quantity | K27: Unit Price USD | L27: Total USD
A28: =I2 -> PO04786 | B28: TCW6649-6303 | C28: Knit | D28: W Flint Pant | E28: Ashwood | F28: Pants | G28: Womens | H28: 53% Organic Cotton, 45% Recycled Polyester, 2% Spandex | I28: 6104.62.62.20 | J28: 27 | K28: 23.35 | L28: =J28*K28 -> 630.45 | M28: 39.69 | N28: 52.92
A29: =A28 -> PO04786 | B29: TCW6649-0164 | C29: Knit | D29: =D28 -> W Flint Pant | E29: Meteorite Black | F29: Pants | G29: Womens | H29: 53% Organic Cotton, 45% Recycled Polyester, 2% Spandex | I29: 6104.62.62.20 | J29: 29 | K29: 23.35 | L29: =J29*K29 -> 677.15
A30: =A28 -> PO04786 | B30: TCM6684-6303 | C30: Knit | D30: M Clark Pant | E30: Ashwood | F30: Pants | G30: Mens | H30: 53% Organic Cotton, 45% Recycled Polyester, 2% Spandex | I30: 6103.42.62.20 | J30: 18 | K30: 25.4 | L30: =J30*K30 -> 457.2 | M30: 45 | N30: 60
A31: =A30 -> PO04786 | B31: TCM6684-0164 | C31: Knit | D31: =D30 -> M Clark Pant | E31: Meteorite Black | F31: Pants | G31: Mens | H31: =H30 -> 53% Organic Cotton, 45% Recycled Polyester, 2% Spandex | I31: 6103.42.62.20 | J31: 51 | K31: 25.4 | L31: =J31*K31 -> 1295.4
A32: =A28 -> PO04786 | B32: TCM6797-0164 | C32: Woven | D32: M Simcoe Pant | E32: Cedar Bark | F32: Pants | G32: Mens | H32: 90% Recycled Polyester, 10% Spandex | I32: 6203.43.62.10 | J32: 5 | K32: 22.11 | L32: =J32*K32 -> 110.55 | M32: 38.14 | N32: 57.21
A33: =A30 -> PO04786 | B33: TCW5674-6391 | C33: Woven | D33: W Yaletown Skirt | E33: Meteorite Black/Meadowland Ditsy | F33: Pants | G33: Womens | H33: 100% ECOVERO -Sustainable Viscose by Lenzing | I33: 6204.63.62.10 | J33: 9 | K33: 14.73 | L33: =J33*K33 -> 132.57 | M33: 23.1 | N33: 34.65
J35: =SUM(J28:J34) -> 139 | L35: =SUM(L28:L34) -> 3303.32
A36: Say Tn Words Total US Dollars: | C36: Three thousand three hundred three and cents thirty two only | N36: =52.94*6 -> 317.64 | P36: =52.92*6 -> 317.52
N37: 161.6 | P37: 160
A38: Additional Remarks
A40: UNITED OVERSEAS BANK | G40: CONTINENT 8 PTE LTD | N40: =5865.64-N36-N37 -> 5386.4
A41: 80 RAFFLES PLACE, UOB PLAZA, SINGAPORE | N41: =N40+P36+P37 -> 5863.92
A42: 48624
A43: Swift: UOVBSGSGXXX | N43: =N41-L35 -> 2560.6
A44: Acccount#: 4509022652 (USD)

Sheet PL-PO04786
A1: =+'INV-PO04774'!A2 -> CONTINENT 8 PTE LTD
A2: =+'INV-PO04774'!A3 -> 300 TAMPINES AVENUE 5, #. 09-02,
A3: =+'INV-PO04774'!A4 -> INCOME AT TAMPINES JUNCTION SINGAPORE 529653
A4: =+'INV-PO04774'!A5 -> AT TAMPINES JUNCTION SINGAPORE 529653
A5: PACKING LIST
J6: PO # | K6: =+'INV-PO04786'!I2 -> PO04786
A7: Consignee | F7: Notify Party | J7: Invoice NO. | K7: =+'INV-PO04786'!I3 -> 022C8P2605AW26.A
A8: Tentree c/o NRI Distribution Inc. | F8: =+'INV-PO04774'!D15 -> Tentree International Canada | J8: S/C NO. | K8: -
A9: 9988 Redwood Avenue | F9: =+'INV-PO04774'!D16 -> 230-1275 Venables St. | J9: Packinglist No. | K9: =K7 -> 022C8P2605AW26.A
A10: LH Building | F10: =+'INV-PO04774'!D17 -> Vancouver, BC V6A 2E4 | J10: DATE: | K10: =+'INV-PO04786'!I4 -> 46149
A11: Fontana, California | F11: =+'INV-PO04774'!D18 -> Canada | J11: PAGE: | K11: 1-1
A12: 1.323.345.6456 | F12: =+'INV-PO04774'!D19 -> +7789897887
A13: 92335, United States | F13: =+'INV-PO04774'!D20 -> logstics@tentree.com
A14: Contact: Yarumi Padilla
A15: 1.323.345.6456
A16: yarumi.padilla@nri-distribution.com
A17: Carrier Appointment Email
A19: CTN # | D19: PO # | E19: SKU | F19: UPC | G19: Style Description | H19: Color Description | I19: TOTAL CTN | J19: TOTAL PCS/CTN | K19: TOTAL PCS | L19: N/W (Kgs) | M19: G/W (Kgs) | N19: MEASURE (M3) | O19: MEASURE (CM)
A21: 1 | B21: - | C21: =+A21+I21-1 -> 1 | D21: =K6 -> PO04786 | E21: TCW6649-6303-2 | F21: 661814875897 | G21: =+'INV-PO04786'!D28 -> W Flint Pant | H21: =+'INV-PO04786'!E28 -> Ashwood | I21: 1 | J21: 2 | K21: =J21+J22+J23+J24+J25+J26+J27 -> 27 | L21: =540*J21/1000+560*J22/1000+580*J23/1000+600*J24/1000+620*J25/1000+640*J26/1000+660*J27/1000 -> 16.06 | M21: =1.65+L21 -> 17.71 | N21: 80 X 44 X 25 | O21: 2 | P21: 285 | Q21: 661814875897 | R21: 2
E22: TCW6649-6303-4 | F22: 661814875873 | J22: 5 | Q22: 661814875873 | R22: 4
E23: TCW6649-6303-6 | F23: 661814875859 | J23: 6 | Q23: 661814875859 | R23: 6
E24: TCW6649-6303-8 | F24: 661814875835 | J24: 5 | Q24: 661814875835 | R24: 8
E25: TCW6649-6303-10 | F25: 661814875972 | J25: 4 | Q25: 661814875972 | R25: 10
E26: TCW6649-6303-12 | F26: 661814875958 | J26: 4 | Q26: 661814875958 | R26: 12
E27: TCW6649-6303-14 | F27: 661814875934 | J27: 1 | Q27: 661814875934 | R27: 14
A28: =A21+I21 -> 2 | B28: - | C28: =+A28+I28-1 -> 2 | E28: TCW6649-0164-2 | F28: 661814876030 | H28: =+'INV-PO04786'!E29 -> Meteorite Black | I28: 1 | J28: 5 | K28: =J28+J29+J30+J31+J32+J33+J34 -> 29 | L28: =540*J28/1000+560*J29/1000+580*J30/1000+600*J31/1000+620*J32/1000+640*J33/1000+660*J34/1000 -> 17.12 | M28: =1.65+L28 -> 18.77 | N28: 80 X 44 X 25 | Q28: 661814876030 | R28: 2
E29: TCW6649-0164-4 | F29: 661814876016 | J29: 5 | Q29: 661814876016 | R29: 4
E30: TCW6649-0164-6 | F30: 661814875996 | J30: 5 | Q30: 661814875996 | R30: 6
E31: TCW6649-0164-8 | F31: 661814876054 | J31: 5 | Q31: 661814876054 | R31: 8
E32: TCW6649-0164-10 | F32: 661814876139 | J32: 4 | Q32: 661814876139 | R32: 10
E33: TCW6649-0164-12 | F33: 661814876115 | J33: 3 | Q33: 661814876115 | R33: 12
E34: TCW6649-0164-14 | F34: 661814876092 | J34: 2 | Q34: 661814876092 | R34: 14
A35: 1 | B35: - | C35: =+A35+I35-1 -> 1 | D35: =K6 -> PO04786 | E35: TCM6684-6303-30 | F35: 661814885612 | G35: =+'INV-PO04786'!D30 -> M Clark Pant | H35: =+'INV-PO04786'!E30 -> Ashwood | I35: 1 | J35: 3 | K35: =SUM(J35:J41) -> 18 | L35: =540*J35/1000+560*J36/1000+580*J37/1000+600*J38/1000+620*J39/1000+640*J40/1000+660*J41/1000 -> 10.82 | M35: =1.65+L35 -> 12.47 | N35: 80 X 44 X 25 | O35: 2 | P35: 285 | Q35: 661814885612 | R35: 30
E36: TCM6684-6303-31 | F36: 661814885599 | J36: 1 | Q36: 661814885599 | R36: 31
E37: TCM6684-6303-32 | F37: 661814885575 | J37: 4 | Q37: 661814885575 | R37: 32
E38: TCM6684-6303-33 | F38: 661814885551 | J38: 1 | Q38: 661814885551 | R38: 33
E39: TCM6684-6303-34 | F39: 661814885537 | J39: 4 | Q39: 661814885537 | R39: 34
E40: TCM6684-6303-36 | F40: 661814885513 | J40: 3 | Q40: 661814885513 | R40: 36
E41: TCM6684-6303-38 | F41: 661814885490 | J41: 2 | Q41: 661814885490 | R41: 38
A42: =A35+I35 -> 2 | B42: - | C42: =+A42+I42-1 -> 2 | E42: TCM6684-0164-30 | F42: 661814885773 | H42: =+'INV-PO04786'!E31 -> Meteorite Black | I42: 1 | J42: 8 | K42: =J42+J43+J44+J45 -> 26 | L42: =540*J42/1000+560*J43/1000+580*J44/1000+600*J45/1000 -> 14.84 | M42: =1.65+L42 -> 16.49 | N42: 80 X 44 X 25 | Q42: 661814885773 | R42: 30
...

Sheet CCI
B2: Revenue Canada | D2: Revenu Canada | E2: CANADA CUSTOMS INVOICE | O2: Page
B3: Customs and Excise | D3: Douanes et Accise | E3: FACTURE DES DOUANES CANADIANNES | O3: 1 | P3: of de1
A5: 1. Vendor (Name and Address)/Vendeur (Nom et adresse) | F5: 2. Date of Direct Shipment to Canada / Date d'expedition directe vers le Canada
A6: =+[16]INVOICE!A2 -> CONTINENT 8 PTE LTD | G6: =+'INV-PO04774'!I3 -> 022C8P2605AW26
A7: =+[16]INVOICE!A3 -> 300 TAMPINES AVENUE 5, #. 09-02,
A8: =+[16]INVOICE!A4 -> INCOME AT TAMPINES JUNCTION SINGAPORE 529653 | F8: 3. Other References (Include Purchaser's Order No.)
A9: =+[16]INVOICE!A5 -> AT TAMPINES JUNCTION SINGAPORE 529653 | F9: Autres references (inclure le no de commande de l'acheteur)
A11: 4. Consignee (Name and Address)/Destinataire (Nom et adresse) | F11: 5. Purchaser's Name and Address (if other than Consignee)
A12: =+[16]INVOICE!A15 -> NRI CA Warehouse (Ecomm) | F12: Nom et adresse de l'acheteur (S'il differe du destinataire)
A13: =+[16]INVOICE!A16 -> tentree c/o NRI Distribution Inc. - receiving
A14: =+[16]INVOICE!A17 -> 8205 Dallas Dr | F14: 6. Country of Transhipment / Pays de transbordement
A15: =+[16]INVOICE!A18 -> Kamloops, BC
A16: =+[16]INVOICE!A19 -> V2C 6X2, Canada | F16: 7. Country of Origin of Goods | K16: PACKINGSLIP NUMBER | N16: =G6 -> 022C8P2605AW26
A17: =+[16]INVOICE!A20 -> Contact: Alyssa Clisby | F17: Pays d'origine des marchandises | K17: PAYMENT TERM | M17: TT AFTER SIGHT
A18: =+[16]INVOICE!A21 -> 250 573 2619 | F18: INDONESIA
A19: =+[16]INVOICE!A22 -> Alyssa.Clisby@nri-distribution.com
A20: 8. Transportation : Give Mode and Place of Direct Shipment to Canada | F20: 9. Conditions of Sale and Terms of Payment
A21: Transport : Preciser mode et point d'expedition directe vers le Canada | F21: (i.e. Sale, Consignment Shipment, Leased Goods, etc.)
A22: SHIPPED BY: | B22: =+'INV-PO04774'!I5 -> SEA (INCRES 072N) | F22: Conditions de vente et modalites de paiement
A23: FROM : | B23: =+'INV-PO04774'!I9 -> JAKARTA, INDONESIA | F23: (p. ex. Vente, expedition en consignation, location de marchandises, etc.)
A24: TO : | B24: =+'INV-PO04774'!I10 -> LOS ANGLES, USA
A25: DATE : | B25: =+'INV-PO04774'!I7 -> 46153 | F25: 10. Currency of Settlement / Devises du paiement | K25: USD
A27: 11. No of | B27: 12. Spesification of Commodities (Kind of Packages, Marks and Numbers, General | K27: 13. Quantity | M27: Selling Price / Prix de vente
A28: Pkgs | B28: Description and Characteristics, I.e. Grade, Quality) | K28: (State Unit) | M28: 14. Unit Price | O28: 15. Total
A29: Nbre de | B29: Designation des articles (Nature des colis, marques et numeros, description generale | K29: Quantite | M29: Prix unitaire
A30: colis | B30: et caracteristiques, p. ex. Classe, qualite) | K30: (Preciser l'unite)
A31: =+#REF! -> #REF! | B31: PO#. | C31: =+[16]INVOICE!J2 -> PO04515
B32: STYLE-COLOR | C32: HS CODE | D32: UPC# | E32: DESCRIPTION | F32: CATAGORY | G32: GENDER | H32: COMPOSITION
B33: =+'INV-PO04774'!#REF! -> #REF! | C33: =+'INV-PO04774'!#REF! -> #REF! | D33: =+#REF! -> #REF! | E33: =+'INV-PO04774'!#REF! -> #REF! | F33: =+'INV-PO04774'!#REF! -> #REF! | G33: =+'INV-PO04774'!#REF! -> #REF! | H33: =+'INV-PO04774'!#REF! -> #REF! | K33: =+'INV-PO04774'!#REF! -> #REF! | L33: PCS | M33: USD | N33: =+'INV-PO04774'!#REF! -> #REF! | O33: USD | P33: =N33*K33 -> #REF!
B34: =+'INV-PO04774'!#REF! -> #REF! | C34: =+'INV-PO04774'!#REF! -> #REF! | D34: =+#REF! -> #REF! | E34: =+'INV-PO04774'!#REF! -> #REF! | F34: =+'INV-PO04774'!#REF! -> #REF! | G34: =+'INV-PO04774'!#REF! -> #REF! | H34: =+'INV-PO04774'!#REF! -> #REF! | K34: =+'INV-PO04774'!#REF! -> #REF! | L34: PCS | M34: USD | N34: =+'INV-PO04774'!#REF! -> #REF! | O34: USD | P34: =N34*K34 -> #REF!
B35: =+'INV-PO04774'!B28 -> TCW6649-6303 | C35: =+'INV-PO04774'!I28 -> 6104.62.62.20 | D35: =+#REF! -> #REF! | E35: =+'INV-PO04774'!D28 -> W Flint Pant | F35: =+'INV-PO04774'!F28 -> Pants | G35: =+'INV-PO04774'!G28 -> Womens | H35: =+'INV-PO04774'!H28 -> 53% Organic Cotton, 45% Recycled Polyester, 2% Spandex | K35: =+'INV-PO04774'!J28 -> 40 | L35: PCS | M35: USD | N35: =+'INV-PO04774'!K28 -> 23.35 | O35: USD | P35: =N35*K35 -> 934
B36: =+'INV-PO04774'!#REF! -> #REF! | C36: =+'INV-PO04774'!#REF! -> #REF! | D36: =+#REF! -> #REF! | E36: =+'INV-PO04774'!#REF! -> #REF! | F36: =+'INV-PO04774'!#REF! -> #REF! | G36: =+'INV-PO04774'!#REF! -> #REF! | H36: =+'INV-PO04774'!#REF! -> #REF! | K36: =+'INV-PO04774'!#REF! -> #REF! | L36: PCS | M36: USD | N36: =+'INV-PO04774'!#REF! -> #REF! | O36: USD | P36: =N36*K36 -> #REF!
B37: =+'INV-PO04774'!B30 -> TCM6684-6303 | C37: =+'INV-PO04774'!I30 -> 6103.42.62.20 | D37: =+#REF! -> #REF! | E37: =+'INV-PO04774'!D30 -> M Clark Pant | F37: =+'INV-PO04774'!F30 -> Pants | G37: =+'INV-PO04774'!G30 -> Mens | H37: =+'INV-PO04774'!H30 -> 53% Organic Cotton, 45% Recycled Polyester, 2% Spandex | K37: =+'INV-PO04774'!#REF! -> #REF! | L37: PCS | M37: USD | N37: =+'INV-PO04774'!#REF! -> #REF! | O37: USD | P37: =N37*K37 -> #REF!
B38: =+'INV-PO04774'!#REF! -> #REF! | C38: =+'INV-PO04774'!#REF! -> #REF! | D38: =+#REF! -> #REF! | E38: =+'INV-PO04774'!#REF! -> #REF! | F38: =+'INV-PO04774'!#REF! -> #REF! | G38: =+'INV-PO04774'!#REF! -> #REF! | H38: =+'INV-PO04774'!#REF! -> #REF! | K38: =+'INV-PO04774'!J35 -> 35 | L38: PCS | M38: USD | N38: =+'INV-PO04774'!K35 -> 27.48 | O38: USD | P38: =N38*K38 -> 961.8
B39: =+'INV-PO04774'!B32 -> TCW6648-6303 | C39: =+'INV-PO04774'!I32 -> 6204.63.62.10 | D39: =+#REF! -> #REF! | E39: =+'INV-PO04774'!D32 -> W Breton Pant | F39: =+'INV-PO04774'!F32 -> Pants | G39: =+'INV-PO04774'!G32 -> Womens | H39: =+'INV-PO04774'!H32 -> 90% Recycled Polyester, 10% Spandex | K39: =+'INV-PO04774'!#REF! -> #REF! | L39: PCS | M39: USD | N39: =+'INV-PO04774'!#REF! -> #REF! | O39: USD | P39: =N39*K39 -> #REF!
B40: =+'INV-PO04774'!#REF! -> #REF! | C40: =+'INV-PO04774'!#REF! -> #REF! | D40: =+#REF! -> #REF! | E40: =+'INV-PO04774'!#REF! -> #REF! | F40: =+'INV-PO04774'!#REF! -> #REF! | G40: =+'INV-PO04774'!#REF! -> #REF! | H40: =+'INV-PO04774'!#REF! -> #REF! | K40: =+'INV-PO04774'!#REF! -> #REF! | L40: PCS | M40: USD | N40: =+'INV-PO04774'!#REF! -> #REF! | O40: USD | P40: =N40*K40 -> #REF!
B41: =+'INV-PO04774'!#REF! -> #REF! | C41: =+'INV-PO04774'!#REF! -> #REF! | D41: =+#REF! -> #REF! | E41: =+'INV-PO04774'!#REF! -> #REF! | F41: =+'INV-PO04774'!#REF! -> #REF! | G41: =+'INV-PO04774'!#REF! -> #REF! | H41: =+'INV-PO04774'!#REF! -> #REF! | K41: =+'INV-PO04774'!J38 -> 46 | L41: PCS | M41: USD | N41: =+'INV-PO04774'!K38 -> 22.11 | O41: USD | P41: =N41*K41 -> 1017.06
B42: =+'INV-PO04774'!#REF! -> #REF! | C42: =+'INV-PO04774'!#REF! -> #REF! | D42: =+#REF! -> #REF! | E42: =+'INV-PO04774'!#REF! -> #REF! | F42: =+'INV-PO04774'!#REF! -> #REF! | G42: =+'INV-PO04774'!#REF! -> #REF! | H42: =+'INV-PO04774'!#REF! -> #REF! | K42: =+'INV-PO04774'!#REF! -> #REF! | L42: PCS | M42: USD | N42: =+'INV-PO04774'!#REF! -> #REF! | O42: USD | P42: =N42*K42 -> #REF!
B43: =+'INV-PO04774'!B35 -> TCM6685-6289 | C43: =+'INV-PO04774'!I35 -> 6203.43.62.10 | D43: =+#REF! -> #REF! | E43: =+'INV-PO04774'!D35 -> M Cameron Pant | F43: =+'INV-PO04774'!F35 -> Pants | G43: =+'INV-PO04774'!G35 -> Mens | H43: =+'INV-PO04774'!H35 -> 90% Recycled Polyester, 10% Spandex | K43: =+'INV-PO04774'!#REF! -> #REF! | L43: PCS | M43: USD | N43: =+'INV-PO04774'!#REF! -> #REF! | O43: USD | P43: =N43*K43 -> #REF!
B44: =+'INV-PO04774'!#REF! -> #REF! | C44: =+'INV-PO04774'!#REF! -> #REF! | D44: =+#REF! -> #REF! | E44: =+'INV-PO04774'!#REF! -> #REF! | F44: =+'INV-PO04774'!#REF! -> #REF! | G44: =+'INV-PO04774'!#REF! -> #REF! | H44: =+'INV-PO04774'!#REF! -> #REF! | K44: =+'INV-PO04774'!#REF! -> #REF! | L44: PCS | M44: USD | N44: =+'INV-PO04774'!#REF! -> #REF! | O44: USD | P44: =N44*K44 -> #REF!
...

Sheet Instructions
A2: Tentree Commercial Invoice Instructions
A4: PO# | B4: Fill in PO number
A5: SKU# | B5: Use the full SKU number: style-color-size (TCM6418-6010-L)
A6: UPC# | B6: Use the corresponding UPC code related to the full SKU
A7: Knit/Woven | B7: Indicate if the item is Knitten or Woven, if neither insert "No"
A8: Style Description | B8: Written style description
A9: Color Description | B9: Written color description
A10: Category | B10: Choose from Dropdown
A11: Gender | B11: Choose from Dropdown (Men/Woman/Ungendered)
A12: Composition | B12: Written composition
A13: HTS Code | B13: Fill in HTS Code
A14: Quantity | B14: Quantity
A15: Unit Price | B15: Unit Price
A16: Total USD | B16: Quantity *Unit Price
